<?xml version="1.0" encoding="utf-8"?>

<robot name="cartopole" xmlns:xacro="http://www.ros.org/wiki/xacro">

  <xacro:arg name="controller" default="joint_position_controller"/>

  <link name="world"/>
  <link name="slideBar">
    <visual>
      <geometry>
        <box size="30 0.05 0.05"/>
      </geometry>
      <origin xyz="0 0 0"/>
    </visual>
    <inertial>
      <mass value="100"/>
      <inertia ixx="1.0" ixy="0.0" ixz="0.0" iyy="1.0" iyz="0.0" izz="1.0"/>
    </inertial>
  </link>
  <link name="cart">
    <visual>
      <geometry>
        <box size="0.5 0.5 0.2"/>
      </geometry>
      <origin xyz="0 0 0"/>
    </visual>
    <inertial>
      <mass value="1"/>
      <inertia ixx="1.0" ixy="0.0" ixz="0.0" iyy="1.0" iyz="0.0" izz="1.0"/>
    </inertial>
  </link>
  <joint name="world_to_base" type="fixed">
    <origin rpy="0 0 0" xyz="0 0 1"/>
    <parent link="world"/>
    <child link="slideBar"/>
  </joint>
  <joint name="slider_to_cart" type="prismatic">
    <axis xyz="1 0 0"/>
    <origin xyz="0.0 0.0 0.0"/>
    <parent link="slideBar"/>
    <child link="cart"/>
    <limit effort="1000.0" lower="-15" upper="15" velocity="30"/>
    <dynamics damping="0.0" friction="0.0"/>
  </joint>

  <gazebo reference="slideBar">
    <visual>
      <material>
        <ambient>0 0.8 0 1</ambient>
        <diffuse>0 0.8 0 1</diffuse>
        <specular>0 0.8 0 1</specular>
      </material>
    </visual>
  </gazebo>

  <gazebo reference="cart">
    <visual>
      <material>
        <ambient>0 0 0.8 1</ambient>
        <diffuse>0 0 0.8 1</diffuse>
        <specular>0 0 0.8 1</specular>
      </material>
    </visual>
  </gazebo>

  <gazebo>
    <plugin filename="ign_ros_control_plugin" name="ign_ros_control::IgnitionROSControlPlugin">
        <updateRate>1000</updateRate>
    </plugin>
  </gazebo>

  <xacro:property name="controller_type" value="$(arg controller)"/>

  <xacro:if value="${controller_type == 'joint_position_controller'}">
    <transmission name="slider_to_cart_trans">
       <type>transmission_interface/SimpleTransmission</type>
       <joint name="slider_to_cart">
          <hardwareInterface>hardware_interface/PositionJointInterface</hardwareInterface>
       </joint>
       <actuator name="slider_to_cart_motor">
          <hardwareInterface>hardware_interface/PositionJointInterface</hardwareInterface>
          <mechanicalReduction>1</mechanicalReduction>
       </actuator>
    </transmission>
  </xacro:if>

  <xacro:if value="${controller_type == 'joint_velocity_controller'}">
    <transmission name="slider_to_cart_trans">
       <type>transmission_interface/SimpleTransmission</type>
       <joint name="slider_to_cart">
          <hardwareInterface>hardware_interface/VelocityJointInterface</hardwareInterface>
       </joint>
       <actuator name="slider_to_cart_motor">
          <hardwareInterface>hardware_interface/VelocityJointInterface</hardwareInterface>
          <mechanicalReduction>1</mechanicalReduction>
       </actuator>
    </transmission>
  </xacro:if>

  <xacro:if value="${controller_type == 'joint_effort_controller'}">
    <transmission name="slider_to_cart_trans">
       <type>transmission_interface/SimpleTransmission</type>
       <joint name="slider_to_cart">
          <hardwareInterface>hardware_interface/EffortJointInterface</hardwareInterface>
       </joint>
       <actuator name="slider_to_cart_motor">
          <hardwareInterface>hardware_interface/EffortJointInterface</hardwareInterface>
          <mechanicalReduction>1</mechanicalReduction>
       </actuator>
    </transmission>
  </xacro:if>

</robot>

